package com.gtocore.common.machine.multiblock.electric.nano;

import com.gtocore.api.data.tag.GTOTagPrefix;
import com.gtocore.api.pattern.GTOPredicates;
import com.gtocore.common.data.GTOBlocks;
import com.gtocore.common.data.GTOMaterials;
import com.gtocore.common.data.GTORecipeDataKeys;

import com.gtolib.api.machine.feature.multiblock.IParallelMachine;
import com.gtolib.api.machine.multiblock.StorageMultiblockMachine;

import com.gregtechceu.gtceu.api.blockentity.MetaMachineBlockEntity;
import com.gregtechceu.gtceu.api.data.chemical.ChemicalHelper;
import com.gregtechceu.gtceu.api.data.chemical.material.Material;
import com.gregtechceu.gtceu.api.data.chemical.material.stack.MaterialStack;
import com.gregtechceu.gtceu.api.machine.MultiblockMachineDefinition;
import com.gregtechceu.gtceu.api.pattern.BlockPattern;
import com.gregtechceu.gtceu.api.pattern.FactoryBlockPattern;
import com.gregtechceu.gtceu.api.recipe.GTRecipe;
import com.gregtechceu.gtceu.api.recipe.handler.RecipeHandlerUnit;
import com.gregtechceu.gtceu.api.recipe.modifier.ParallelLogic;
import com.gregtechceu.gtceu.api.recipe.modifier.RecipeModifier;
import com.gregtechceu.gtceu.common.data.GTBlocks;
import com.gregtechceu.gtceu.common.data.GTMaterials;

import net.minecraft.MethodsReturnNonnullByDefault;

import com.gto.datasynclib.annotations.SaveToDisk;
import com.gto.datasynclib.annotations.SyncToClient;
import it.unimi.dsi.fastutil.ints.Int2ObjectOpenHashMap;
import org.jetbrains.annotations.Nullable;

import java.util.function.Supplier;

import javax.annotation.ParametersAreNonnullByDefault;

import static com.gregtechceu.gtceu.api.machine.multiblock.PartAbility.*;
import static com.gregtechceu.gtceu.api.pattern.Predicates.*;

@ParametersAreNonnullByDefault
@MethodsReturnNonnullByDefault
public final class NanoForgeMachine extends StorageMultiblockMachine implements IParallelMachine {

    private static final Int2ObjectOpenHashMap<BlockPattern> PATTERNS = new Int2ObjectOpenHashMap<>(4, 0.9F);

    @SaveToDisk
    @SyncToClient
    private int machineTier;

    public NanoForgeMachine(MetaMachineBlockEntity holder) {
        super(holder, 64, i -> ChemicalHelper.getPrefix(i.getItem()) == GTOTagPrefix.NANITES);
    }

    @Nullable
    @Override
    protected GTRecipe getRealRecipe(RecipeHandlerUnit unit, GTRecipe recipe) {
        if (recipe.data.getInt(GTORecipeDataKeys.NANO_FORGE_TIER) > machineTier) {
            return null;
        }
        recipe = ParallelLogic.accurateParallel(this, unit, recipe, getParallel() * (1L << (machineTier - recipe.data.getInt(GTORecipeDataKeys.NANO_FORGE_TIER))));
        if (recipe == null) return null;
        return RecipeModifier.overclocking(this, unit, recipe, false, 1, 1, machineTier > recipe.data.getInt(GTORecipeDataKeys.NANO_FORGE_TIER) ? 0.25 : 0.5);
    }

    @Override
    public void onMachineChanged() {
        machineTier = 0;
        MaterialStack stack = ChemicalHelper.getMaterialStack(getStorageStack());
        if (stack.isEmpty()) return;
        Material material = stack.material();
        if (material == GTMaterials.Carbon) {
            machineTier = 1;
        } else if (material == GTOMaterials.Amprosium) {
            machineTier = 2;
        } else if (material == GTOMaterials.Draconium) {
            machineTier = 3;
        }
        requestCheck();
    }

    public static BlockPattern getBlockPattern(int tier, MultiblockMachineDefinition definition) {
        return PATTERNS.computeIfAbsent(tier, t -> {
            FactoryBlockPattern builder = FactoryBlockPattern.start(definition)
                    .where('~', controller(definition))
                    .where(' ', any());
            return switch (t) {
                case 2 -> builder.aisle("                   ", "                   ", "                   ", "                   ", "                   ", "                   ", "                   ", "                   ", "                   ", "                   ", "                   ", "                   ", "    A              ", "    A              ", "    A              ", "    A              ", "    A              ", "    A              ", "    A              ", "    A              ", "                   ", "                   ", "                   ", "                   ", "                   ", "                   ", "                   ", "                   ", "                   ", "                   ", "                   ", "                   ", "                   ", "                   ", "                   ", "                   ", "                   ", "                   ")
                        .aisle("  CCCCC            ", "                   ", "                   ", "                   ", "                   ", "                   ", "                   ", "                   ", "   DAD             ", "   DAD             ", "   DAD             ", "   DAD             ", "   DAD             ", "   DAD             ", "   DAD             ", "   DAD             ", "   DAD             ", "   DAD             ", "   DAD             ", "   DAD             ", "   DAD             ", "   DAD             ", "   DAD             ", "   DAD             ", "                   ", "                   ", "                   ", "                   ", "                   ", "                   ", "                   ", "                   ", "                   ", "                   ", "                   ", "                   ", "                   ", "                   ")
                        .aisle(" CAAAAAC           ", "   DAD             ", "   DAD             ", "   DAD             ", "   DAD             ", "   DAD             ", "   DAD             ", "   DAD             ", "  DA AD            ", "  DA AD            ", "  DA AD            ", "  DA AD            ", "  AA AA            ", "  AA AA            ", "  AA AA            ", "  AA AA            ", "  AA AA            ", "  AA AA            ", "  AA AA            ", "  AA AA            ", "  DA AD            ", "  DA AD            ", "  DA AD            ", "  DA AD            ", "   DAD             ", "   DAD             ", "   DAD             ", "   DAD             ", "   DAD             ", "   DAD             ", "   DAD             ", "   DAD             ", "   DAD             ", "    D              ", "    D              ", "    D              ", "    D              ", "    D              ")
                        .aisle("CAAAAAAAC          ", "   A A             ", "   A A             ", "   A A             ", "   A A             ", "   A A             ", "   A A             ", "   A A             ", "   A A             ", "   A A             ", "  A   A            ", "  A   A            ", "  A   A            ", "  A   A            ", "  A   A            ", " AA   AA           ", " AA   AA           ", "  A   A            ", "  A   A            ", "  A   A            ", "  A   A            ", "  A   A            ", "   A A             ", "   A A             ", "   A A             ", "   A A             ", "   A A             ", "   A A             ", "   A A             ", "   A A             ", "   A A             ", "   A A             ", "   A A             ", "    A              ", "    A              ", "    A              ", "    A              ", "    A              ")
                        .aisle("CAAAAAAAC          ", "   A A             ", "   A A             ", "   A A             ", "   A A             ", "   A A             ", "   A A             ", "   A A             ", "   A A             ", "   A A             ", "  A   A            ", "  A   A            ", "  A   A            ", "  A   A            ", "  A   A            ", " AA   AA           ", " AA   AA           ", "  A   A            ", "  A   A            ", "  A   A            ", "  A   A            ", "  A   A            ", "   A A             ", "   A A             ", "   A A             ", "   A A             ", "   A A             ", "   A A             ", "   A A             ", "   A A             ", "   A A             ", "   A A             ", "   A A             ", "    A              ", "    A              ", "    A              ", "    A              ", "    A              ")
                        .aisle("CAAAAAAAC   AAAAAA ", "   A A             ", "   A A             ", "   A A             ", "   A A             ", "   A A             ", "   A A             ", "   A A             ", "   A A             ", "   A A             ", "  A   A            ", "  A   A            ", "  A   A            ", "  A   A            ", "  A   A            ", " AA   AA           ", " AA   AA           ", "  A   A            ", "  A   A            ", "  A   A            ", "  A   A            ", "  A   A            ", "   A A             ", "   A A             ", "   A A             ", "   A A             ", "   A A             ", "   A A             ", "   A A             ", "   A A             ", "   A A             ", "   A A             ", "   A A             ", "    A              ", "    A              ", "    A              ", "    A              ", "    A              ")
                        .aisle("CAAAAAAAC  AAAAAAAA", "   A A             ", "   A A             ", "   A A             ", "   A A             ", "   A A             ", "   A A             ", "   A A             ", "   A A             ", "   A A             ", "  A   A            ", "  A   A            ", "  A   A            ", "  A   A            ", "  A   A            ", " AA   AA           ", " AA   AA           ", "  A   A            ", "  A   A            ", "  A   A            ", "  A   A            ", "  A   A            ", "   A A             ", "   A A             ", "   A A             ", "   A A             ", "   A A             ", "   A A             ", "   A A             ", "   A A             ", "   A A             ", "   A A             ", "   A A             ", "    A              ", "    A              ", "    A              ", "    A              ", "    A              ")
                        .aisle(" CAAAAAC   AAAAAAAA", "   DAD             ", "   DAD             ", "   DAD             ", "   DAD             ", "   DAD        AA   ", "   DAD        BB   ", "   DAD        AA   ", "  DA AD            ", "  DA AD            ", "  DA AD            ", "  DA AD            ", "  AA AA       AA   ", "  AA AA       BB   ", "  AA AA       AA   ", "  AA AA            ", "  AA AA            ", "  AA AA            ", "  AA AA            ", "  AA AA            ", "  DA AD            ", "  DA AD            ", "  DA AD            ", "  DA AD            ", "   DAD             ", "   DAD             ", "   DAD             ", "   DAD             ", "   DAD             ", "   DAD             ", "   DAD             ", "   DAD             ", "   DAD             ", "    D              ", "    D              ", "    D              ", "    D              ", "    D              ")
                        .aisle("  CC~CC    AAAAAAAA", "              AA   ", "              AA   ", "              AA   ", "              AA   ", "             AAAA  ", "             BAAB  ", "             AAAA  ", "   DAD        AA   ", "   DAD        AA   ", "   DAD        AA   ", "   DAD        AA   ", "   DAD       AAAA  ", "   DAD       BAAB  ", "   DAD       AAAA  ", "   DAD             ", "   DAD             ", "   DAD             ", "   DAD             ", "   DAD             ", "   DAD             ", "   DAD             ", "   DAD             ", "   DAD             ", "                   ", "                   ", "                   ", "                   ", "                   ", "                   ", "                   ", "                   ", "                   ", "                   ", "                   ", "                   ", "                   ", "                   ")
                        .aisle("           AAAAAAAA", "              AA   ", "              AA   ", "              AA   ", "              AA   ", "             AAAA  ", "             BAAB  ", "             AAAA  ", "              AA   ", "              AA   ", "              AA   ", "              AA   ", "    A        AAAA  ", "    A        BAAB  ", "    A        AAAA  ", "    A              ", "    A              ", "    A              ", "    A              ", "    A              ", "                   ", "                   ", "                   ", "                   ", "                   ", "                   ", "                   ", "                   ", "                   ", "                   ", "                   ", "                   ", "                   ", "                   ", "                   ", "                   ", "                   ", "                   ")
                        .aisle("           AAAAAAAA", "                   ", "                   ", "                   ", "                   ", "              AA   ", "              BB   ", "              AA   ", "                   ", "                   ", "                   ", "                   ", "              AA   ", "              BB   ", "              AA   ", "                   ", "                   ", "                   ", "                   ", "                   ", "                   ", "                   ", "                   ", "                   ", "                   ", "                   ", "                   ", "                   ", "                   ", "                   ", "                   ", "                   ", "                   ", "                   ", "                   ", "                   ", "                   ", "                   ")
                        .aisle("           AAAAAAAA", "                   ", "                   ", "                   ", "                   ", "                   ", "                   ", "                   ", "                   ", "                   ", "                   ", "                   ", "                   ", "                   ", "                   ", "                   ", "                   ", "                   ", "                   ", "                   ", "                   ", "                   ", "                   ", "                   ", "                   ", "                   ", "                   ", "                   ", "                   ", "                   ", "                   ", "                   ", "                   ", "                   ", "                   ", "                   ", "                   ", "                   ")
                        .aisle("            AAAAAA ", "                   ", "                   ", "                   ", "                   ", "                   ", "                   ", "                   ", "                   ", "                   ", "                   ", "                   ", "                   ", "                   ", "                   ", "                   ", "                   ", "                   ", "                   ", "                   ", "                   ", "                   ", "                   ", "                   ", "                   ", "                   ", "                   ", "                   ", "                   ", "                   ", "                   ", "                   ", "                   ", "                   ", "                   ", "                   ", "                   ", "                   ")
                        .where('A', blocks(GTOBlocks.NAQUADAH_ALLOY_CASING.get()))
                        .where('C', blocks(GTOBlocks.NAQUADAH_ALLOY_CASING.get())
                                .or(abilities(IMPORT_ITEMS))
                                .or(abilities(EXPORT_ITEMS))
                                .or(abilities(IMPORT_FLUIDS))
                                .or(abilities(INPUT_LASER)))
                        .where('B', blocks(GTBlocks.CASING_ASSEMBLY_LINE.get()))
                        .where('D', GTOPredicates.frame(GTMaterials.Ruridit))
                        .build();
                case 3 -> builder.aisle("                             ", "                             ", "                             ", "                             ", "                             ", "                             ", "                             ", "                             ", "                             ", "                             ", "                             ", "                             ", "              A              ", "              A              ", "              A              ", "              A              ", "              A              ", "              A              ", "              A              ", "              A              ", "                             ", "                             ", "                             ", "                             ", "                             ", "                             ", "                             ", "                             ", "                             ", "                             ", "                             ", "                             ", "                             ", "                             ", "                             ", "                             ", "                             ", "                             ")
                        .aisle("            DDDDD            ", "                             ", "                             ", "                             ", "                             ", "                             ", "                             ", "                             ", "             CAC             ", "             CAC             ", "             CAC             ", "             CAC             ", "             CAC             ", "             CAC             ", "             CAC             ", "             CAC             ", "             CAC             ", "             CAC             ", "             CAC             ", "             CAC             ", "             CAC             ", "             CAC             ", "             CAC             ", "             CAC             ", "                             ", "                             ", "                             ", "                             ", "                             ", "                             ", "                             ", "                             ", "                             ", "                             ", "                             ", "                             ", "                             ", "                             ")
                        .aisle("           DAAAAAD           ", "             CAC             ", "             CAC             ", "             CAC             ", "             CAC             ", "             CAC             ", "             CAC             ", "             CAC             ", "            CA AC            ", "            CA AC            ", "            CA AC            ", "            CA AC            ", "            AA AA            ", "            AA AA            ", "            AA AA            ", "            AA AA            ", "            AA AA            ", "            AA AA            ", "            AA AA            ", "            AA AA            ", "            CA AC            ", "            CA AC            ", "            CA AC            ", "            CA AC            ", "             CAC             ", "             CAC             ", "             CAC             ", "             CAC             ", "             CAC             ", "             CAC             ", "             CAC             ", "             CAC             ", "             CAC             ", "              C              ", "              C              ", "              C              ", "              C              ", "              C              ")
                        .aisle("          DAAAAAAAD          ", "             A A             ", "             A A             ", "             A A             ", "             A A             ", "             A A             ", "             A A             ", "             A A             ", "             A A             ", "             A A             ", "            A   A            ", "            A   A            ", "            A   A            ", "            A   A            ", "            A   A            ", "           AA   AA           ", "           AA   AA           ", "            A   A            ", "            A   A            ", "            A   A            ", "            A   A            ", "            A   A            ", "             A A             ", "             A A             ", "             A A             ", "             A A             ", "             A A             ", "             A A             ", "             A A             ", "             A A             ", "             A A             ", "             A A             ", "             A A             ", "              A              ", "              A              ", "              A              ", "              A              ", "              A              ")
                        .aisle("          DAAAAAAAD          ", "             A A             ", "             A A             ", "             A A             ", "             A A             ", "             A A             ", "             A A             ", "             A A             ", "             A A             ", "             A A             ", "            A   A            ", "            A   A            ", "            A   A            ", "            A   A            ", "            A   A            ", "           AA   AA           ", "           AA   AA           ", "            A   A            ", "            A   A            ", "            A   A            ", "            A   A            ", "            A   A            ", "             A A             ", "             A A             ", "             A A             ", "             A A             ", "             A A             ", "             A A             ", "             A A             ", "             A A             ", "             A A             ", "             A A             ", "             A A             ", "              A              ", "              A              ", "              A              ", "              A              ", "              A              ")
                        .aisle(" AAAAAA   DAAAAAAAD   AAAAAA ", "             A A             ", "    CC       A A             ", "  CC         A A             ", "             A A             ", "             A A             ", "             A A             ", "             A A             ", "    CC       A A             ", "  CC         A A             ", "            A   A            ", "            A   A            ", "            A   A            ", "            A   A            ", "    CC      A   A            ", "  CC       AA   AA           ", "           AA   AA           ", "            A   A            ", "            A   A            ", "            A   A            ", "    CC      A   A            ", "  CC        A   A            ", "             A A             ", "             A A             ", "             A A             ", "             A A             ", "             A A             ", "             A A             ", "             A A             ", "             A A             ", "             A A             ", "             A A             ", "             A A             ", "              A              ", "              A              ", "              A              ", "              A              ", "              A              ")
                        .aisle("AAAAAAAA  DAAAAAAAD  AAAAAAAA", "      C      A A             ", "             A A             ", "             A A             ", " C           A A             ", "             A A             ", "             A A             ", "      C      A A             ", "             A A             ", "             A A             ", " C          A   A            ", "            A   A            ", "            A   A            ", "      C     A   A            ", "            A   A            ", "           AA   AA           ", " C         AA   AA           ", "            A   A            ", "            A   A            ", "      C     A   A            ", "            A   A            ", "            A   A            ", " C           A A             ", "             A A             ", "             A A             ", "             A A             ", "             A A             ", "             A A             ", "             A A             ", "             A A             ", "             A A             ", "             A A             ", "             A A             ", "              A              ", "              A              ", "              A              ", "              A              ", "              A              ")
                        .aisle("AAAAAAAA   DAAAAAD   AAAAAAAA", "             CAC             ", "             CAC             ", "             CAC             ", "   AA        CAC             ", "C  BB        CAC        AA   ", "   AA  C     CAC        BB   ", "             CAC        AA   ", "            CA AC            ", "            CA AC            ", "            CA AC            ", "C           CA AC            ", "       C    AA AA       AA   ", "            AA AA       BB   ", "   AA       AA AA       AA   ", "   AA       AA AA            ", "   AA       AA AA            ", "C  AA       AA AA            ", "       C    AA AA            ", "            AA AA            ", "            CA AC            ", "            CA AC            ", "            CA AC            ", "C           CA AC            ", "   AA  C     CAC             ", "   BBCC      CAC             ", "   AA        CAC             ", "             CAC             ", "             CAC             ", "             CAC             ", "             CAC             ", "             CAC             ", "             CAC             ", "              C              ", "              C              ", "              C              ", "              C              ", "              C              ")
                        .aisle("AAAAAAAA    DD~DD    AAAAAAAA", "   AA                   AA   ", "   AA                   AA   ", "   AA                   AA   ", "  AAAA                  AA   ", "C BAAB                 AAAA  ", "  AAAA C               BAAB  ", "   AA                  AAAA  ", "   AA        CAC        AA   ", "   AA        CAC        AA   ", "   AA        CAC        AA   ", "C  AA        CAC        AA   ", "   AA  C     CAC       AAAA  ", "   AA        CAC       BAAB  ", "  AAAA       CAC       AAAA  ", "  AAAA       CAC             ", "  AAAA       CAC             ", "C AAAA       CAC             ", "   AA  C     CAC             ", "   AA        CAC             ", "   AA        CAC             ", "   AA        CAC             ", "   AA        CAC             ", "C  AA        CAC             ", "  AAAA C                     ", "  BAAB                       ", "  AAAA                       ", "                             ", "                             ", "                             ", "                             ", "                             ", "                             ", "                             ", "                             ", "                             ", "                             ", "                             ")
                        .aisle("AAAAAAAA             AAAAAAAA", "   AA                   AA   ", "   AA                   AA   ", "   AA                   AA   ", "  AAAA                  AA   ", "  BAAB C               AAAA  ", "C AAAA                 BAAB  ", "   AA                  AAAA  ", "   AA                   AA   ", "   AA                   AA   ", "   AA                   AA   ", "   AA  C                AA   ", "C  AA         A        AAAA  ", "   AA         A        BAAB  ", "  AAAA        A        AAAA  ", "  AAAA        A              ", "  AAAA        A              ", "  AAAA C      A              ", "C  AA         A              ", "   AA         A              ", "   AA                        ", "   AA                        ", "   AA                        ", "   AA  C                     ", "C AAAA                       ", "  BAAB                       ", "  AAAA                       ", "                             ", "                             ", "                             ", "                             ", "                             ", "                             ", "                             ", "                             ", "                             ", "                             ", "                             ")
                        .aisle("AAAAAAAA             AAAAAAAA", "                             ", "                             ", "                             ", "   AA                        ", "   BB  C                AA   ", "C  AA                   BB   ", "                        AA   ", "                             ", "                             ", "                             ", "       C                     ", "C                       AA   ", "                        BB   ", "   AA                   AA   ", "   AA                        ", "   AA                        ", "   AA  C                     ", "C                            ", "                             ", "                             ", "                             ", "                             ", "       C                     ", "C  AA                        ", " CCBB                        ", "   AA                        ", "                             ", "                             ", "                             ", "                             ", "                             ", "                             ", "                             ", "                             ", "                             ", "                             ", "                             ")
                        .aisle("AAAAAAAA             AAAAAAAA", " C                           ", "                             ", "                             ", "      C                      ", "                             ", "                             ", " C                           ", "                             ", "                             ", "      C                      ", "                             ", "                             ", " C                           ", "                             ", "                             ", "      C                      ", "                             ", "                             ", " C                           ", "                             ", "                             ", "      C                      ", "                             ", "                             ", "                             ", "                             ", "                             ", "                             ", "                             ", "                             ", "                             ", "                             ", "                             ", "                             ", "                             ", "                             ", "                             ")
                        .aisle(" AAAAAA               AAAAAA ", "                             ", "  CC                         ", "    CC                       ", "                             ", "                             ", "                             ", "                             ", "  CC                         ", "    CC                       ", "                             ", "                             ", "                             ", "                             ", "  CC                         ", "    CC                       ", "                             ", "                             ", "                             ", "                             ", "  CC                         ", "    CC                       ", "                             ", "                             ", "                             ", "                             ", "                             ", "                             ", "                             ", "                             ", "                             ", "                             ", "                             ", "                             ", "                             ", "                             ", "                             ", "                             ")
                        .where('A', blocks(GTOBlocks.NAQUADAH_ALLOY_CASING.get()))
                        .where('D', blocks(GTOBlocks.NAQUADAH_ALLOY_CASING.get())
                                .or(abilities(IMPORT_ITEMS))
                                .or(abilities(EXPORT_ITEMS))
                                .or(abilities(IMPORT_FLUIDS))
                                .or(abilities(INPUT_LASER)))
                        .where('B', blocks(GTOBlocks.ADVANCED_ASSEMBLY_LINE_UNIT.get()))
                        .where('C', GTOPredicates.frame(GTMaterials.Ruridit))
                        .build();
                default -> builder
                        .aisle("         ", "         ", "         ", "         ", "         ", "         ", "         ", "         ", "         ", "         ", "         ", "         ", "    B    ", "    B    ", "    B    ", "    B    ", "    B    ", "    B    ", "    B    ", "    B    ", "         ", "         ", "         ", "         ", "         ", "         ", "         ", "         ", "         ", "         ", "         ", "         ", "         ", "         ", "         ", "         ", "         ", "         ")
                        .aisle("  AAAAA  ", "         ", "         ", "         ", "         ", "         ", "         ", "         ", "   CBC   ", "   CBC   ", "   CBC   ", "   CBC   ", "   CBC   ", "   CBC   ", "   CBC   ", "   CBC   ", "   CBC   ", "   CBC   ", "   CBC   ", "   CBC   ", "   CBC   ", "   CBC   ", "   CBC   ", "   CBC   ", "         ", "         ", "         ", "         ", "         ", "         ", "         ", "         ", "         ", "         ", "         ", "         ", "         ", "         ")
                        .aisle(" ABBBBBA ", "   CBC   ", "   CBC   ", "   CBC   ", "   CBC   ", "   CBC   ", "   CBC   ", "   CBC   ", "  CB BC  ", "  CB BC  ", "  CB BC  ", "  CB BC  ", "  BB BB  ", "  BB BB  ", "  BB BB  ", "  BB BB  ", "  BB BB  ", "  BB BB  ", "  BB BB  ", "  BB BB  ", "  CB BC  ", "  CB BC  ", "  CB BC  ", "  CB BC  ", "   CBC   ", "   CBC   ", "   CBC   ", "   CBC   ", "   CBC   ", "   CBC   ", "   CBC   ", "   CBC   ", "   CBC   ", "    C    ", "    C    ", "    C    ", "    C    ", "    C    ")
                        .aisle("ABBBBBBBA", "   B B   ", "   B B   ", "   B B   ", "   B B   ", "   B B   ", "   B B   ", "   B B   ", "   B B   ", "   B B   ", "  B   B  ", "  B   B  ", "  B   B  ", "  B   B  ", "  B   B  ", " BB   BB ", " BB   BB ", "  B   B  ", "  B   B  ", "  B   B  ", "  B   B  ", "  B   B  ", "   B B   ", "   B B   ", "   B B   ", "   B B   ", "   B B   ", "   B B   ", "   B B   ", "   B B   ", "   B B   ", "   B B   ", "   B B   ", "    B    ", "    B    ", "    B    ", "    B    ", "    B    ")
                        .aisle("ABBBBBBBA", "   B B   ", "   B B   ", "   B B   ", "   B B   ", "   B B   ", "   B B   ", "   B B   ", "   B B   ", "   B B   ", "  B   B  ", "  B   B  ", "  B   B  ", "  B   B  ", "  B   B  ", " BB   BB ", " BB   BB ", "  B   B  ", "  B   B  ", "  B   B  ", "  B   B  ", "  B   B  ", "   B B   ", "   B B   ", "   B B   ", "   B B   ", "   B B   ", "   B B   ", "   B B   ", "   B B   ", "   B B   ", "   B B   ", "   B B   ", "    B    ", "    B    ", "    B    ", "    B    ", "    B    ")
                        .aisle("ABBBBBBBA", "   B B   ", "   B B   ", "   B B   ", "   B B   ", "   B B   ", "   B B   ", "   B B   ", "   B B   ", "   B B   ", "  B   B  ", "  B   B  ", "  B   B  ", "  B   B  ", "  B   B  ", " BB   BB ", " BB   BB ", "  B   B  ", "  B   B  ", "  B   B  ", "  B   B  ", "  B   B  ", "   B B   ", "   B B   ", "   B B   ", "   B B   ", "   B B   ", "   B B   ", "   B B   ", "   B B   ", "   B B   ", "   B B   ", "   B B   ", "    B    ", "    B    ", "    B    ", "    B    ", "    B    ")
                        .aisle("ABBBBBBBA", "   B B   ", "   B B   ", "   B B   ", "   B B   ", "   B B   ", "   B B   ", "   B B   ", "   B B   ", "   B B   ", "  B   B  ", "  B   B  ", "  B   B  ", "  B   B  ", "  B   B  ", " BB   BB ", " BB   BB ", "  B   B  ", "  B   B  ", "  B   B  ", "  B   B  ", "  B   B  ", "   B B   ", "   B B   ", "   B B   ", "   B B   ", "   B B   ", "   B B   ", "   B B   ", "   B B   ", "   B B   ", "   B B   ", "   B B   ", "    B    ", "    B    ", "    B    ", "    B    ", "    B    ")
                        .aisle(" ABBBBBA ", "   CBC   ", "   CBC   ", "   CBC   ", "   CBC   ", "   CBC   ", "   CBC   ", "   CBC   ", "  CB BC  ", "  CB BC  ", "  CB BC  ", "  CB BC  ", "  BB BB  ", "  BB BB  ", "  BB BB  ", "  BB BB  ", "  BB BB  ", "  BB BB  ", "  BB BB  ", "  BB BB  ", "  CB BC  ", "  CB BC  ", "  CB BC  ", "  CB BC  ", "   CBC   ", "   CBC   ", "   CBC   ", "   CBC   ", "   CBC   ", "   CBC   ", "   CBC   ", "   CBC   ", "   CBC   ", "    C    ", "    C    ", "    C    ", "    C    ", "    C    ")
                        .aisle("  AA~AA  ", "         ", "         ", "         ", "         ", "         ", "         ", "         ", "   CBC   ", "   CBC   ", "   CBC   ", "   CBC   ", "   CBC   ", "   CBC   ", "   CBC   ", "   CBC   ", "   CBC   ", "   CBC   ", "   CBC   ", "   CBC   ", "   CBC   ", "   CBC   ", "   CBC   ", "   CBC   ", "         ", "         ", "         ", "         ", "         ", "         ", "         ", "         ", "         ", "         ", "         ", "         ", "         ", "         ")
                        .where('B', blocks(GTOBlocks.NAQUADAH_ALLOY_CASING.get()))
                        .where('A', blocks(GTOBlocks.NAQUADAH_ALLOY_CASING.get())
                                .or(abilities(IMPORT_ITEMS))
                                .or(abilities(EXPORT_ITEMS))
                                .or(abilities(IMPORT_FLUIDS))
                                .or(abilities(INPUT_LASER)))
                        .where('C', GTOPredicates.frame(GTMaterials.Ruridit)).build();
            };
        });
    }

    @Override
    public Supplier<BlockPattern>[] getPattern() {
        return new Supplier[] { () -> getBlockPattern(machineTier, getDefinition()) };
    }

    @Override
    public long getMaxParallel() {
        return machineTier > 0 ? getStorageStack().getCount() : 0;
    }

    @Override
    public long getMinParallel() {
        return Math.min(IParallelMachine.MIN_PARALLEL, getMaxParallel());
    }
}
